Workbook

Sheet Listado
A1: FAMILIA | B1: DNI | C1: CONTACTO | D1: DIRECCIÓN | E1: COMP. FAMILIAR | F1: RESPONSABLE
A2: Marisol Benitez Gimenez | B2: 95097978 | C2: 2257-410680 | D2: Torino 1950 | E2: 5 | F2: Alicia
A3: Karen Zalazar | B3: 41150179 | C3: 011-21922121 | D3: Palacio 1123 | E3: 6 | F3: Alicia
A4: Maria Rosa Astudillo | B4: 22062236 | C4: 2257-648821 | D4: Lebensohn 913 | E4: 3 | F4: Alicia
A5: Juliana Garay | B5: 26949108 | C5: - | D5: Blanco Encalada 1328 | F5: Alicia
A6: Domingo Di Genova | B6: 16979387 | F6: Alicia
A7: America Anriquez | B7: 11897226 | C7: 2257-421838 | D7: Ramos Mejia 1350 | E7: 2 | F7: Alicia
A8: Denis Moyano | B8: 40302862 | C8: 2257-408408 | D8: Ramos Mejia 2434 | E8: 3 | F8: Alicia
A9: Ramon Lujan | D9: Olmos 290 | F9: Alicia
A10: Rocio Rossi | B10: 40861647 | C10: 2257-512433 | D10: Lebensohn 156 | E10: 4 | F10: Alicia
A11: Ramon Aranda | B11: 5319601 | D11: Olmos 290 | E11: 2 | F11: Alicia
A12: Cristina Yamila Gomez | B12: 37198780 | C12: 011-53194731 | D12: Lobo de Mar 905 | E12: 3 | F12: Alicia
A13: Rosa Carolina Claverie | B13: 23983141 | C13: 2257-409329 | D13: Lugones 352 | E13: 2 | F13: Alicia
A14: Miguel Angel Morel | B14: 14421874 | C14: 2257-314091 | D14: Azopardo 1648 | E14: 2 | F14: Alicia
A15: Juan Ramon Podazza | B15: 17067721 | C15: 2257-524437 | D15: Espora 2348 | E15: 4 | F15: Alicia
A16: Leila Daiana Barrionuevo | B16: 41196195 | C16: 2257-558726 | D16: Blanco Encalada 2281 | E16: 3 | F16: Alicia
A17: Irupé Alejandra Chaparro | B17: 40256430 | C17: 2257-550465 | D17: Olmos y Pueyrredon (Casa 3) | E17: 3 | F17: Alicia
A18: Marcela Alejandra Gomez | B18: 22404551 | C18: 2257-405238 | D18: Olmos 224 | E18: 3 | F18: Alicia
A19: Veronica Andrea Paszukievicz | B19: 23087773 | C19: 011-58719913 | D19: Pueyrredon 520 | E19: 1 | F19: Alicia
A20: Isabel Mercedes Torancio | B20: 18538454 | C20: 2257-309831 | D20: Olmos y Pueyrredon (Casa 1) | E20: 3 | F20: Alicia
A21: Camila Naomi Vergara | B21: 44335274 | C21: 2257-406648 | D21: Ushuaia 1545 | E21: 3 | F21: Alicia | G21: Repetido con Luciana
A22: Daiana Melisa Falcon | B22: 32656564 | C22: 2257-307509 | D22: Argentina 1360 | E22: 3 | F22: Alicia
A23: Erica Elizabeth Devia | B23: 24529624 | C23: 2257-403871 | D23: Libres del Sur 289 | E23: 4 | F23: Alicia
A24: Ana María Astudillo | B24: 20460132 | C24: 2257-408306 | D24: Sarandí 1700 | E24: 3 | F24: Alicia
A25: Puntilio Maria | B25: 10154202 | C25: - | D25: Olmos 218 | F25: Alicia
A26: Mirta Beatiz Deareys | B26: 20315674 | C26: 2257-615278 | D26: Blanco Encalada 2281 | E26: 1 | F26: Alicia
A27: Ana Rosa Benitez | B27: 6219667 | C27: 2257-610506 | D27: Calvetti 627 | E27: 1 | F27: Alicia
A28: Judith Araceli Cardenas | B28: 22789930 | C28: 011-31156064 | D28: La Margarita 342 | E28: 1 | F28: Alicia
A29: Benjamin Nieves | B29: 48636953 | C29: 2257-543060 | D29: Tierra del Fuego 1941 | E29: 3 | F29: Alicia | G29: Coincidencia con moni
A30: Felisa Colqui | B30: 9987622 | C30: 2257-408408 | D30: Hernandez 665 | E30: 4 | F30: Alicia
A31: Santa Cecilia Gularte | B31: 30792577 | C31: 2257-417827 | D31: Ascasubi 589 | E31: 6 | F31: Alicia
A32: Funes Pablo | B32: 32197277 | C32: - | D32: Hernandez 665 | F32: Alicia
A33: Gloria Diaz | B33: 13295827 | D33: Diag. Cobo 840 | E33: 5 | F33: Alicia
A34: Dora Funes | B34: 27283186 | C34: 2257-408408 | D34: Caseros 150 | E34: 4 | F34: Alicia
A35: Berlinda Raquel Lagraña Caballero | B35: 95845820 | C35: 2257-554584 | D35: El Ancla 920 | E35: 3 | F35: Alicia
A36: Amelia Noemí Castro | B36: 11730351 | C36: 2257-648754 | D36: Olmos y Espora 234 | E36: 1 | F36: Alicia
A37: Eva Martina Casco | B37: 10637796 | C37: 2257-503835 | D37: Montevideo 411 | E37: 2 | F37: Alicia
A38: Ana Maria Correa | B38: 18228361 | C38: - | D38: Marano 1078 | E38: 1 | F38: Alicia
A39: Estefania Geraldine Sosa | B39: 47397463 | C39: 2257-543067 | D39: Tierra del Fuego 1541 | E39: 2 | F39: Alicia
A40: Marina Moreno | B40: 23452403 | C40: 2257-534587 | D40: Azopardo 2056 | E40: 1 | F40: Alicia
...

Sheet Sin asignar
A1: FAMILIA | B1: DNI | C1: CONTACTO | D1: DIRECCION | E1: COMP. FAMILIAR | F1: RESPONSABLE
A2: Adrian Claudio Lopez | B2: 23127346 | C2: - | D2: Newbery y Sarmiento | E2: 1 | F2: Local
A3: Axel Gauna | B3: 42946946 | C3: 2257-409784 | D3: Solis 2003 | E3: 2 | F3: Local
A4: Fabian San Pedro | B4: 16564850 | C4: 2257-539719 | D4: Azopardo 2115 | E4: 1 | F4: Local
A5: Leonardo Ferreyra | B5: 11316801 | C5: 23004659 | D5: Montevideo 1186 | E5: 1 | F5: Local
A6: Atilio Beliz | B6: 10296302 | C6: - | D6: Lobo de Mar y Montevideo | E6: 2 | F6: Local
A7: Diego Velozo | B7: 32790206 | C7: - | D7: Pueyrredon 207 | E7: 1 | F7: Local
A8: Andrea De Leonardo | B8: 43582623 | C8: 2257-630662 | D8: Olmos 680 | E8: 2 | F8: Local
A9: Antonio Rodriguez | B9: 21548077 | C9: - | D9: Chascomus 1052 | F9: Local
A10: Nilda Astudillo | B10: 14977856 | C10: 2257-550558 | D10: Sarandi 1453 | E10: 3 | F10: Local
A11: Juan Alberto Serrano | B11: 12913429 | C11: 011-23378516 | D11: Ascasubi 207 | E11: 1 | F11: Local
A12: Juan Carlos Encina | B12: 21306084 | C12: - | D12: Castelli 363 | E12: 1 | F12: Local
A13: Ariel Demetrio | B13: 34589794 | C13: 2254-417843 | D13: Chascomus y Ramos Mejia | E13: 6 | F13: Local
A14: Ramon Sanabria | B14: 22201987 | C14: - | D14: Lebensohn y Azopardo | E14: 1 | F14: Local
A15: Claudio Lopez | B15: 23127346 | C15: - | D15: Situación de Calle | E15: 1 | F15: Local
A16: Patricia Padilla | B16: 32698210 | C16: 011-24761661 | D16: Marano 1191 | E16: 2
A17: Mirta Gomez | B17: 10266238 | C17: 011-22640144 | D17: Guiraldes 1343 | E17: 2
A18: Miguel Sanchez | B18: 8603093 | C18: 011-53294517 | D18: Cramer 624 | E18: 1
A19: Teofilo Lezcano | B19: 93645678 | C19: 2257-610278 | D19: Salta 1033 | E19: 3
A20: Matias Freire | B20: 30533742 | D20: Azopardo 170 | E20: 1
A21: Francisco Gonzalez | B21: 22887783 | D21: Querini y Salta | E21: 3
A22: Ignacio Pelaes | B22: 42070119 | D22: Estanislao del Campo 916 | E22: 3
A23: Maria Ines Aquino | B23: 14688000 | D23: Marano 613 | E23: 2
A24: Manuel Escudero | B24: 5325452 | D24: L. del Sur 339 | E24: 2
A25: Alejandra Escudero | B25: 22322258 | D25: L. del Sur 339 | E25: 2
A26: Dora Mane | B26: 3890534 | D26: Caseros 64 | E26: 2
A27: Mabel Manquez | B27: 92104177 | D27: Guiraldes 1279 | E27: 4
A28: Erica Astudillo | B28: 40021634 | D28: Lebensohn 1593 | E28: 2
A29: Armando Troncoso | B29: 92217967 | D29: R. Mejía y Lebensohn | E29: 1
A30: Pedro Alcaras | B30: 16688717 | D30: Est. del Campo 527 | E30: 5
A31: Sergio Fleytas | B31: 31415461 | D31: Yunque 686 | E31: 3
... A61: Malena Zurita | B61: 44788732 | D61: La Argentina y Sacconi | E61: 3
A62: Beatriz Guzman | D62: Olmos 290 | E62: 1
A63: Elizabeth Sosa | B63: 23847154 | D63: J. Ingenieros 66 | E63: 2
A64: Bianca Benitez | B64: 95322388 | D64: Jujuy 1184 | E64: 2
A65: Mariela Roldan | B65: 40236595 | D65: Julio Campos 960 | E65: 5
A66: Antonella Jara | B66: 41004089 | D66: Colon 20 | E66: 3
A67: Aureliana Ortiz | B67: 94335000 | D67: Dolores 620 | E67: 5
A68: Gladys Fleitas | B68: 11951307 | D68: Tierra del Fuego 1931 | E68: 2
A69: Roxana Francisca Aguirre | B69: 32648777 | D69: Pueyrredon 761 | E69: 2
...

Sheet Backup desactualizado
A1: FAMILIA | B1: DNI | C1: CONTACTO | D1: DIRECCION | E1: COMP. FAMILIAR | F1: RESPONSABLE
A2: Marisol Benitez Gimenez | B2: 95097978 | C2: 2257-410680 | D2: Torino 1950 | E2: 5 | F2: Alicia
A3: Karen Zalazar | B3: 41150179 | C3: 011-21922121 | D3: Palacio 1123 | E3: 6 | F3: Alicia
A4: Maria Rosa Astudillo | B4: 22062236 | C4: 2257-648821 | D4: Lebensohn 913 | E4: 3 | F4: Alicia
A5: Juliana Garay | B5: 26949108 | C5: - | D5: Blanco Encalada 1328 | F5: Alicia
A6: Domingo Di Genova | B6: 16979387 | F6: Alicia
A7: America Anriquez | B7: 11897226 | C7: 2257-421838 | D7: Ramos Mejia 1350 | E7: 2 | F7: Alicia
A8: Denis Moyano | B8: 40302862 | C8: 2257-408408 | D8: Ramos Mejia 2434 | E8: 3 | F8: Alicia
A9: Ramon Lujan | D9: Olmos 290 | F9: Alicia
A10: Rocio Rossi | B10: 40861647 | C10: 2257-512433 | D10: Lebensohn 156 | E10: 4 | F10: Alicia
A11: Ramon Aranda | B11: 5319601 | D11: Olmos 290 | E11: 2 | F11: Alicia
A12: Cristina Yamila Gomez | B12: 37198780 | C12: 011-53194731 | D12: Lobo de Mar 905 | E12: 3 | F12: Alicia
A13: Rosa Carolina Claverie | B13: 23983141 | C13: 2257-409329 | D13: Lugones 352 | E13: 2 | F13: Alicia
A14: Miguel Angel Morel | B14: 14421874 | C14: 2257-314091 | D14: Azopardo 1648 | E14: 2 | F14: Alicia
A15: Juan Ramon Podazza | B15: 17067721 | C15: 2257-524437 | D15: Espora 2348 | E15: 4 | F15: Alicia
A16: Leila Daiana Barrionuevo | B16: 41196195 | C16: 2257-558726 | D16: Blanco Encalada 2281 | E16: 3 | F16: Alicia
A17: Irupé Alejandra Chaparro | B17: 40256430 | C17: 2257-550465 | D17: Olmos y Pueyrredon (Casa 3) | E17: 3 | F17: Alicia
A18: Marcela Alejandra Gomez | B18: 22404551 | C18: 2257-405238 | D18: Olmos 224 | E18: 3 | F18: Alicia
A19: Veronica Andrea Paszukievicz | B19: 23087773 | C19: 011-58719913 | D19: Pueyrredon 520 | E19: 1 | F19: Alicia
A20: Isabel Mercedes Torancio | B20: 18538454 | C20: 2257-309831 | D20: Olmos y Pueyrredon (Casa 1) | E20: 3 | F20: Alicia
A21: Camila Naomi Vergara | B21: 44335274 | C21: 2257-406648 | D21: Ushuaia 1545 | E21: 3 | F21: Alicia | G21: Repetido con Luciana
A22: Daiana Melisa Falcon | B22: 32656564 | C22: 2257-307509 | D22: Argentina 1360 | E22: 3 | F22: Alicia
A23: Erica Elizabeth Devia | B23: 24529624 | C23: 2257-403871 | D23: Libres del Sur 289 | E23: 4 | F23: Alicia
A24: Ana María Astudillo | B24: 20460132 | C24: 2257-408306 | D24: Sarandí 1700 | E24: 3 | F24: Alicia
A25: Puntilio Maria | B25: 10154202 | C25: - | D25: Olmos 218 | F25: Alicia
A26: Mirta Beatiz Deareys | B26: 20315674 | C26: 2257-615278 | D26: Blanco Encalada 2281 | E26: 1 | F26: Alicia
A27: Ana Rosa Benitez | B27: 6219667 | C27: 2257-610506 | D27: Calvetti 627 | E27: 1 | F27: Alicia
A28: Judith Araceli Cardenas | B28: 22789930 | C28: 011-31156064 | D28: La Margarita 342 | E28: 1 | F28: Alicia
A29: Benjamin Nieves | B29: 48636953 | C29: 2257-543060 | D29: Tierra del Fuego 1941 | E29: 3 | F29: Alicia | G29: Coincidencia con moni
A30: Felisa Colqui | B30: 9987622 | C30: 2257-408408 | D30: Hernandez 665 | E30: 4 | F30: Alicia
A31: Santa Cecilia Gularte | B31: 30792577 | C31: 2257-417827 | D31: Ascasubi 589 | E31: 6 | F31: Alicia
A32: Funes Pablo | B32: 32197277 | C32: - | D32: Hernandez 665 | F32: Alicia
A33: Gloria Diaz | B33: 13295827 | D33: Diag. Cobo 840 | E33: 5 | F33: Alicia
A34: Dora Funes | B34: 27283186 | C34: 2257-408408 | D34: Caseros 150 | E34: 4 | F34: Alicia
A35: Berlinda Raquel Lagraña Caballero | B35: 95845820 | C35: 2257-554584 | D35: El Ancla 920 | E35: 3 | F35: Alicia
A36: Amelia Noemí Castro | B36: 11730351 | C36: 2257-648754 | D36: Olmos y Espora 234 | E36: 1 | F36: Alicia
A37: Eva Martina Casco | B37: 10637796 | C37: 2257-503835 | D37: Montevideo 411 | E37: 2 | F37: Alicia
A38: Ana Maria Correa | B38: 18228361 | C38: - | D38: Marano 1078 | E38: 1 | F38: Alicia
A39: Estefania Geraldine Sosa | B39: 47397463 | C39: 2257-543067 | D39: Tierra del Fuego 1541 | E39: 2 | F39: Alicia
A40: Marina Moreno | B40: 23452403 | C40: 2257-534587 | D40: Azopardo 2056 | E40: 1 | F40: Alicia
...

Sheet Mercadería 221025
A1: FAMILIA | B1: DNI | C1: CONTACTO | D1: DIRECCIÓN | E1: COMP. FAMILIAR | F1: RESPONSABLE
A2: {=IFERROR(INDEX(Listado!$A:$A,MATCH($B2,Listado!$B:$B,0)),"")} -> Barbara Cardozo | B2: 31977775 | C2: {=IFERROR(INDEX(Listado!$C:$C,MATCH($B2,Listado!$B:$B,0)),"")} -> - | D2: {=IFERROR(INDEX(Listado!$D:$D,MATCH($B2,Listado!$B:$B,0)),"")} -> Ramos Mejia 819 | E2: {=IFERROR(INDEX(Listado!$E:$E,MATCH($B2,Listado!$B:$B,0)),"")} -> 5 | F2: {=IFERROR(INDEX(Listado!$F:$F,MATCH($B2,Listado!$B:$B,0)),"")} -> Laura
A3: {=IFERROR(INDEX(Listado!$A:$A,MATCH($B3,Listado!$B:$B,0)),"")} -> Carolina Arce | B3: 24999650 | C3: {=IFERROR(INDEX(Listado!$C:$C,MATCH($B3,Listado!$B:$B,0)),"")} -> 2257-526956 | D3: {=IFERROR(INDEX(Listado!$D:$D,MATCH($B3,Listado!$B:$B,0)),"")} -> Olmos 786 | E3: {=IFERROR(INDEX(Listado!$E:$E,MATCH($B3,Listado!$B:$B,0)),"")} -> 6 | F3: {=IFERROR(INDEX(Listado!$F:$F,MATCH($B3,Listado!$B:$B,0)),"")} -> Laura
A4: {=IFERROR(INDEX(Listado!$A:$A,MATCH($B4,Listado!$B:$B,0)),"")} -> Gloria Diaz | B4: 13295827 | C4: {=IFERROR(INDEX(Listado!$C:$C,MATCH($B4,Listado!$B:$B,0)),"")} | D4: {=IFERROR(INDEX(Listado!$D:$D,MATCH($B4,Listado!$B:$B,0)),"")} -> Diag. Cobo 840 | E4: {=IFERROR(INDEX(Listado!$E:$E,MATCH($B4,Listado!$B:$B,0)),"")} -> 5 | F4: {=IFERROR(INDEX(Listado!$F:$F,MATCH($B4,Listado!$B:$B,0)),"")} -> Alicia
A5: {=IFERROR(INDEX(Listado!$A:$A,MATCH($B5,Listado!$B:$B,0)),"")} -> Ayala Silvina | B5: 44839453 | C5: {=IFERROR(INDEX(Listado!$C:$C,MATCH($B5,Listado!$B:$B,0)),"")} | D5: {=IFERROR(INDEX(Listado!$D:$D,MATCH($B5,Listado!$B:$B,0)),"")} -> Guiraldes 1345 | E5: {=IFERROR(INDEX(Listado!$E:$E,MATCH($B5,Listado!$B:$B,0)),"")} | F5: {=IFERROR(INDEX(Listado!$F:$F,MATCH($B5,Listado!$B:$B,0)),"")} -> Laura
A6: {=IFERROR(INDEX(Listado!$A:$A,MATCH($B6,Listado!$B:$B,0)),"")} -> Jose Antonio Elola | B6: 17334862 | C6: {=IFERROR(INDEX(Listado!$C:$C,MATCH($B6,Listado!$B:$B,0)),"")} | D6: {=IFERROR(INDEX(Listado!$D:$D,MATCH($B6,Listado!$B:$B,0)),"")} -> Guiraldes 1120 | E6: {=IFERROR(INDEX(Listado!$E:$E,MATCH($B6,Listado!$B:$B,0)),"")} -> 1 | F6: {=IFERROR(INDEX(Listado!$F:$F,MATCH($B6,Listado!$B:$B,0)),"")} -> Laura
A7: {=IFERROR(INDEX(Listado!$A:$A,MATCH($B7,Listado!$B:$B,0)),"")} -> Solange Villordo | B7: 37243636 | C7: {=IFERROR(INDEX(Listado!$C:$C,MATCH($B7,Listado!$B:$B,0)),"")} | D7: {=IFERROR(INDEX(Listado!$D:$D,MATCH($B7,Listado!$B:$B,0)),"")} -> Castelli 556 | E7: {=IFERROR(INDEX(Listado!$E:$E,MATCH($B7,Listado!$B:$B,0)),"")} | F7: {=IFERROR(INDEX(Listado!$F:$F,MATCH($B7,Listado!$B:$B,0)),"")} -> Luciana
A8: {=IFERROR(INDEX(Listado!$A:$A,MATCH($B8,Listado!$B:$B,0)),"")} -> Vanesa Guillermina Rearte | B8: 36109672 | C8: {=IFERROR(INDEX(Listado!$C:$C,MATCH($B8,Listado!$B:$B,0)),"")} -> 2257-404340 | D8: {=IFERROR(INDEX(Listado!$D:$D,MATCH($B8,Listado!$B:$B,0)),"")} -> Belgrano 1660 | E8: {=IFERROR(INDEX(Listado!$E:$E,MATCH($B8,Listado!$B:$B,0)),"")} -> 5 | F8: {=IFERROR(INDEX(Listado!$F:$F,MATCH($B8,Listado!$B:$B,0)),"")} -> Victoria
A9: {=IFERROR(INDEX(Listado!$A:$A,MATCH($B9,Listado!$B:$B,0)),"")} -> Yessica Marcela Marie | B9: 36953674 | C9: {=IFERROR(INDEX(Listado!$C:$C,MATCH($B9,Listado!$B:$B,0)),"")} -> 2257-547854 | D9: {=IFERROR(INDEX(Listado!$D:$D,MATCH($B9,Listado!$B:$B,0)),"")} -> Cramer 173 | E9: {=IFERROR(INDEX(Listado!$E:$E,MATCH($B9,Listado!$B:$B,0)),"")} -> 4 | F9: {=IFERROR(INDEX(Listado!$F:$F,MATCH($B9,Listado!$B:$B,0)),"")} -> Victoria
A10: {=IFERROR(INDEX(Listado!$A:$A,MATCH($B10,Listado!$B:$B,0)),"")} -> Graciela Silvia Rossano | B10: 14977811 | C10: {=IFERROR(INDEX(Listado!$C:$C,MATCH($B10,Listado!$B:$B,0)),"")} -> 2257-636856 | D10: {=IFERROR(INDEX(Listado!$D:$D,MATCH($B10,Listado!$B:$B,0)),"")} -> La Margarita 163 | E10: {=IFERROR(INDEX(Listado!$E:$E,MATCH($B10,Listado!$B:$B,0)),"")} -> 3 | F10: {=IFERROR(INDEX(Listado!$F:$F,MATCH($B10,Listado!$B:$B,0)),"")} -> Victoria
A11: {=IFERROR(INDEX(Listado!$A:$A,MATCH($B11,Listado!$B:$B,0)),"")} -> Maria Cristina Vivardo | B11: 18675269 | C11: {=IFERROR(INDEX(Listado!$C:$C,MATCH($B11,Listado!$B:$B,0)),"")} -> 2257-666044 | D11: {=IFERROR(INDEX(Listado!$D:$D,MATCH($B11,Listado!$B:$B,0)),"")} -> Libres del Sur 640 | E11: {=IFERROR(INDEX(Listado!$E:$E,MATCH($B11,Listado!$B:$B,0)),"")} -> 3 | F11: {=IFERROR(INDEX(Listado!$F:$F,MATCH($B11,Listado!$B:$B,0)),"")} -> Victoria
A12: {=IFERROR(INDEX(Listado!$A:$A,MATCH($B12,Listado!$B:$B,0)),"")} -> Daniela Daiana Nuñez | B12: 18877218 | C12: {=IFERROR(INDEX(Listado!$C:$C,MATCH($B12,Listado!$B:$B,0)),"")} -> 2257-621763 | D12: {=IFERROR(INDEX(Listado!$D:$D,MATCH($B12,Listado!$B:$B,0)),"")} -> Montevideo 1650 | E12: {=IFERROR(INDEX(Listado!$E:$E,MATCH($B12,Listado!$B:$B,0)),"")} -> 3 | F12: {=IFERROR(INDEX(Listado!$F:$F,MATCH($B12,Listado!$B:$B,0)),"")} -> Victoria
A13: {=IFERROR(INDEX(Listado!$A:$A,MATCH($B13,Listado!$B:$B,0)),"")} -> Rocio Magali Ramirez | B13: 42343596 | C13: {=IFERROR(INDEX(Listado!$C:$C,MATCH($B13,Listado!$B:$B,0)),"")} -> 2257-505262 | D13: {=IFERROR(INDEX(Listado!$D:$D,MATCH($B13,Listado!$B:$B,0)),"")} -> Olivieri 1189 | E13: {=IFERROR(INDEX(Listado!$E:$E,MATCH($B13,Listado!$B:$B,0)),"")} -> 5 | F13: {=IFERROR(INDEX(Listado!$F:$F,MATCH($B13,Listado!$B:$B,0)),"")} -> Victoria
... A44: {=IFERROR(INDEX(Listado!$A:$A,MATCH($B44,Listado!$B:$B,0)),"")} -> Agustin Caceres | B44: 37537405 | C44: {=IFERROR(INDEX(Listado!$C:$C,MATCH($B44,Listado!$B:$B,0)),"")} -> 2257-667647 | D44: {=IFERROR(INDEX(Listado!$D:$D,MATCH($B44,Listado!$B:$B,0)),"")} -> Libres del Sur 640 | E44: {=IFERROR(INDEX(Listado!$E:$E,MATCH($B44,Listado!$B:$B,0)),"")} -> 2 | F44: {=IFERROR(INDEX(Listado!$F:$F,MATCH($B44,Listado!$B:$B,0)),"")} -> Victoria
A45: Enzo Caceres | C45: {=IFERROR(INDEX(Listado!$C:$C,MATCH($B45,Listado!$B:$B,0)),"")} | D45: {=IFERROR(INDEX(Listado!$D:$D,MATCH($B45,Listado!$B:$B,0)),"")} | E45: {=IFERROR(INDEX(Listado!$E:$E,MATCH($B45,Listado!$B:$B,0)),"")} | F45: Victoria
A46: {=IFERROR(INDEX(Listado!$A:$A,MATCH($B46,Listado!$B:$B,0)),"")} -> Marcia Melisa Zurita | B46: 39486344 | C46: {=IFERROR(INDEX(Listado!$C:$C,MATCH($B46,Listado!$B:$B,0)),"")} -> 2257-405998 | D46: {=IFERROR(INDEX(Listado!$D:$D,MATCH($B46,Listado!$B:$B,0)),"")} -> Libres del Sur 1441 | E46: {=IFERROR(INDEX(Listado!$E:$E,MATCH($B46,Listado!$B:$B,0)),"")} -> 4 | F46: {=IFERROR(INDEX(Listado!$F:$F,MATCH($B46,Listado!$B:$B,0)),"")} -> Victoria
A47: {=IFERROR(INDEX(Listado!$A:$A,MATCH($B47,Listado!$B:$B,0)),"")} -> Zurita Malena | B47: 44788732 | C47: {=IFERROR(INDEX(Listado!$C:$C,MATCH($B47,Listado!$B:$B,0)),"")} -> 11-58393718 | D47: {=IFERROR(INDEX(Listado!$D:$D,MATCH($B47,Listado!$B:$B,0)),"")} -> La Argentina y Rawson | E47: {=IFERROR(INDEX(Listado!$E:$E,MATCH($B47,Listado!$B:$B,0)),"")} -> 4 | F47: {=IFERROR(INDEX(Listado!$F:$F,MATCH($B47,Listado!$B:$B,0)),"")} -> Victoria
A48: {=IFERROR(INDEX(Listado!$A:$A,MATCH($B48,Listado!$B:$B,0)),"")} -> Rincon Vanina | B48: 23477368 | C48: {=IFERROR(INDEX(Listado!$C:$C,MATCH($B48,Listado!$B:$B,0)),"")} -> 11-58393718 | D48: {=IFERROR(INDEX(Listado!$D:$D,MATCH($B48,Listado!$B:$B,0)),"")} -> Libres del Sur 1441 | E48: {=IFERROR(INDEX(Listado!$E:$E,MATCH($B48,Listado!$B:$B,0)),"")} -> 2 | F48: {=IFERROR(INDEX(Listado!$F:$F,MATCH($B48,Listado!$B:$B,0)),"")} -> Victoria
A49: {=IFERROR(INDEX(Listado!$A:$A,MATCH($B49,Listado!$B:$B,0)),"")} -> Maribel Garcia Hinojosa | B49: 95119965 | C49: {=IFERROR(INDEX(Listado!$C:$C,MATCH($B49,Listado!$B:$B,0)),"")} -> 2257-445488 | D49: {=IFERROR(INDEX(Listado!$D:$D,MATCH($B49,Listado!$B:$B,0)),"")} -> Calvetti 2020 | E49: {=IFERROR(INDEX(Listado!$E:$E,MATCH($B49,Listado!$B:$B,0)),"")} -> 3 | F49: {=IFERROR(INDEX(Listado!$F:$F,MATCH($B49,Listado!$B:$B,0)),"")} -> Victoria
A50: {=IFERROR(INDEX(Listado!$A:$A,MATCH($B50,Listado!$B:$B,0)),"")} -> Maria Soledad Impala | B50: 16345755 | C50: {=IFERROR(INDEX(Listado!$C:$C,MATCH($B50,Listado!$B:$B,0)),"")} -> - | D50: {=IFERROR(INDEX(Listado!$D:$D,MATCH($B50,Listado!$B:$B,0)),"")} -> Quinteros 1017 | E50: {=IFERROR(INDEX(Listado!$E:$E,MATCH($B50,Listado!$B:$B,0)),"")} -> 2 | F50: {=IFERROR(INDEX(Listado!$F:$F,MATCH($B50,Listado!$B:$B,0)),"")} -> Laura
A51: {=IFERROR(INDEX(Listado!$A:$A,MATCH($B51,Listado!$B:$B,0)),"")} -> Soledad Mener | B51: 34458572 | C51: {=IFERROR(INDEX(Listado!$C:$C,MATCH($B51,Listado!$B:$B,0)),"")} -> 2257-404180 | D51: {=IFERROR(INDEX(Listado!$D:$D,MATCH($B51,Listado!$B:$B,0)),"")} -> Torino 820 | E51: {=IFERROR(INDEX(Listado!$E:$E,MATCH($B51,Listado!$B:$B,0)),"")} -> 4 | F51: {=IFERROR(INDEX(Listado!$F:$F,MATCH($B51,Listado!$B:$B,0)),"")} -> Luciana
A52: {=IFERROR(INDEX(Listado!$A:$A,MATCH($B52,Listado!$B:$B,0)),"")} -> Angela Olmedo | B52: 30294101 | C52: {=IFERROR(INDEX(Listado!$C:$C,MATCH($B52,Listado!$B:$B,0)),"")} | D52: {=IFERROR(INDEX(Listado!$D:$D,MATCH($B52,Listado!$B:$B,0)),"")} -> Guiraldes 1342 | E52: {=IFERROR(INDEX(Listado!$E:$E,MATCH($B52,Listado!$B:$B,0)),"")} | F52: {=IFERROR(INDEX(Listado!$F:$F,MATCH($B52,Listado!$B:$B,0)),"")} -> Laura
A53: {=IFERROR(INDEX(Listado!$A:$A,MATCH($B53,Listado!$B:$B,0)),"")} -> Omar Balmaceda | B53: 17050472 | C53: {=IFERROR(INDEX(Listado!$C:$C,MATCH($B53,Listado!$B:$B,0)),"")} | D53: {=IFERROR(INDEX(Listado!$D:$D,MATCH($B53,Listado!$B:$B,0)),"")} -> Calvetti 1589 | E53: {=IFERROR(INDEX(Listado!$E:$E,MATCH($B53,Listado!$B:$B,0)),"")} -> 1 | F53: {=IFERROR(INDEX(Listado!$F:$F,MATCH($B53,Listado!$B:$B,0)),"")} -> Laura
A54: {=IFERROR(INDEX(Listado!$A:$A,MATCH($B54,Listado!$B:$B,0)),"")} -> Hector Martin Balmaceda | B54: 37537744 | C54: {=IFERROR(INDEX(Listado!$C:$C,MATCH($B54,Listado!$B:$B,0)),"")} -> 2257-542576 | D54: {=IFERROR(INDEX(Listado!$D:$D,MATCH($B54,Listado!$B:$B,0)),"")} -> Calvetti y Lobo de Mar (Casa 9) | E54: {=IFERROR(INDEX(Listado!$E:$E,MATCH($B54,Listado!$B:$B,0)),"")} -> 2 | F54: {=IFERROR(INDEX(Listado!$F:$F,MATCH($B54,Listado!$B:$B,0)),"")} -> Alicia
A55: Rocio Ruiz | C55: 2257-549353 | D55: Lobo de Mar 960 | E55: 3 | F55: Laura
A56: {=IFERROR(INDEX(Listado!$A:$A,MATCH($B56,Listado!$B:$B,0)),"")} -> Carlos Maximiliano Trullenque | B56: 19084601 | C56: {=IFERROR(INDEX(Listado!$C:$C,MATCH($B56,Listado!$B:$B,0)),"")} | D56: {=IFERROR(INDEX(Listado!$D:$D,MATCH($B56,Listado!$B:$B,0)),"")} | E56: {=IFERROR(INDEX(Listado!$E:$E,MATCH($B56,Listado!$B:$B,0)),"")} -> 3 | F56: {=IFERROR(INDEX(Listado!$F:$F,MATCH($B56,Listado!$B:$B,0)),"")} -> Laura
A57: Lopez Elizabeth | B57: 22513419 | C57: {=IFERROR(INDEX(Listado!$C:$C,MATCH($B57,Listado!$B:$B,0)),"")} | D57: {=IFERROR(INDEX(Listado!$D:$D,MATCH($B57,Listado!$B:$B,0)),"")} | E57: {=IFERROR(INDEX(Listado!$E:$E,MATCH($B57,Listado!$B:$B,0)),"")} | F57: Laura
A58: {=IFERROR(INDEX(Listado!$A:$A,MATCH($B58,Listado!$B:$B,0)),"")} -> Norma Beatriz Pacheco | B58: 34737811 | C58: {=IFERROR(INDEX(Listado!$C:$C,MATCH($B58,Listado!$B:$B,0)),"")} -> 2257-403865 | D58: {=IFERROR(INDEX(Listado!$D:$D,MATCH($B58,Listado!$B:$B,0)),"")} -> Diagonal correa morales 461 | E58: {=IFERROR(INDEX(Listado!$E:$E,MATCH($B58,Listado!$B:$B,0)),"")} -> 2 | F58: {=IFERROR(INDEX(Listado!$F:$F,MATCH($B58,Listado!$B:$B,0)),"")} -> Laura
A59: {=IFERROR(INDEX(Listado!$A:$A,MATCH($B59,Listado!$B:$B,0)),"")} -> Noelia Susana Bustamante | B59: 31741983 | C59: {=IFERROR(INDEX(Listado!$C:$C,MATCH($B59,Listado!$B:$B,0)),"")} -> 011-51747824 | D59: {=IFERROR(INDEX(Listado!$D:$D,MATCH($B59,Listado!$B:$B,0)),"")} -> Quinteros 170 | E59: {=IFERROR(INDEX(Listado!$E:$E,MATCH($B59,Listado!$B:$B,0)),"")} -> 4 | F59: {=IFERROR(INDEX(Listado!$F:$F,MATCH($B59,Listado!$B:$B,0)),"")} -> Laura
A60: {=IFERROR(INDEX(Listado!$A:$A,MATCH($B60,Listado!$B:$B,0)),"")} -> Paula Ayelen Mezza | B60: 34503540 | C60: {=IFERROR(INDEX(Listado!$C:$C,MATCH($B60,Listado!$B:$B,0)),"")} -> 011-65325987 | D60: {=IFERROR(INDEX(Listado!$D:$D,MATCH($B60,Listado!$B:$B,0)),"")} -> Caseros Esquina Drago y Libertador | E60: {=IFERROR(INDEX(Listado!$E:$E,MATCH($B60,Listado!$B:$B,0)),"")} -> 2 | F60: {=IFERROR(INDEX(Listado!$F:$F,MATCH($B60,Listado!$B:$B,0)),"")} -> Victoria
A61: {=IFERROR(INDEX(Listado!$A:$A,MATCH($B61,Listado!$B:$B,0)),"")} -> Hortencia Galvan | B61: 12735647 | C61: {=IFERROR(INDEX(Listado!$C:$C,MATCH($B61,Listado!$B:$B,0)),"")} | D61: {=IFERROR(INDEX(Listado!$D:$D,MATCH($B61,Listado!$B:$B,0)),"")} -> Libres del Sur 1468 | E61: {=IFERROR(INDEX(Listado!$E:$E,MATCH($B61,Listado!$B:$B,0)),"")} | F61: {=IFERROR(INDEX(Listado!$F:$F,MATCH($B61,Listado!$B:$B,0)),"")} -> Laura
A62: {=IFERROR(INDEX(Listado!$A:$A,MATCH($B62,Listado!$B:$B,0)),"")} -> Fabian Gomez | B62: 24574010 | C62: {=IFERROR(INDEX(Listado!$C:$C,MATCH($B62,Listado!$B:$B,0)),"")} -> 011-28328288 | D62: {=IFERROR(INDEX(Listado!$D:$D,MATCH($B62,Listado!$B:$B,0)),"")} -> Guiraldes 1342 | E62: {=IFERROR(INDEX(Listado!$E:$E,MATCH($B62,Listado!$B:$B,0)),"")} -> 5 | F62: {=IFERROR(INDEX(Listado!$F:$F,MATCH($B62,Listado!$B:$B,0)),"")} -> Laura
A63: {=IFERROR(INDEX(Listado!$A:$A,MATCH($B63,Listado!$B:$B,0)),"")} -> Farrase Maria Regina | B63: 30146471 | C63: {=IFERROR(INDEX(Listado!$C:$C,MATCH($B63,Listado!$B:$B,0)),"")} -> 2257-669344 | D63: {=IFERROR(INDEX(Listado!$D:$D,MATCH($B63,Listado!$B:$B,0)),"")} | E63: {=IFERROR(INDEX(Listado!$E:$E,MATCH($B63,Listado!$B:$B,0)),"")} -> 2 | F63: {=IFERROR(INDEX(Listado!$F:$F,MATCH($B63,Listado!$B:$B,0)),"")} -> Laura
A64: {=IFERROR(INDEX(Listado!$A:$A,MATCH($B64,Listado!$B:$B,0)),"")} -> Ramon Aranda | B64: 5319601 | C64: {=IFERROR(INDEX(Listado!$C:$C,MATCH($B64,Listado!$B:$B,0)),"")} | D64: {=IFERROR(INDEX(Listado!$D:$D,MATCH($B64,Listado!$B:$B,0)),"")} -> Olmos 290 | E64: {=IFERROR(INDEX(Listado!$E:$E,MATCH($B64,Listado!$B:$B,0)),"")} -> 2 | F64: {=IFERROR(INDEX(Listado!$F:$F,MATCH($B64,Listado!$B:$B,0)),"")} -> Alicia
A65: {=IFERROR(INDEX(Listado!$A:$A,MATCH($B65,Listado!$B:$B,0)),"")} -> Guzman Elda Beatriz | B65: 11730341 | C65: {=IFERROR(INDEX(Listado!$C:$C,MATCH($B65,Listado!$B:$B,0)),"")} -> - | D65: {=IFERROR(INDEX(Listado!$D:$D,MATCH($B65,Listado!$B:$B,0)),"")} -> Olmos 290 | E65: {=IFERROR(INDEX(Listado!$E:$E,MATCH($B65,Listado!$B:$B,0)),"")} -> 1 | F65: {=IFERROR(INDEX(Listado!$F:$F,MATCH($B65,Listado!$B:$B,0)),"")} -> Alicia
A66: {=IFERROR(INDEX(Listado!$A:$A,MATCH($B66,Listado!$B:$B,0)),"")} -> Alicia Noemi Morel | B66: 27739220 | C66: {=IFERROR(INDEX(Listado!$C:$C,MATCH($B66,Listado!$B:$B,0)),"")} -> 11-73632680 | D66: {=IFERROR(INDEX(Listado!$D:$D,MATCH($B66,Listado!$B:$B,0)),"")} -> Julio Campo 150 | E66: {=IFERROR(INDEX(Listado!$E:$E,MATCH($B66,Listado!$B:$B,0)),"")} -> 1 | F66: {=IFERROR(INDEX(Listado!$F:$F,MATCH($B66,Listado!$B:$B,0)),"")} -> Alicia
A67: {=IFERROR(INDEX(Listado!$A:$A,MATCH($B67,Listado!$B:$B,0)),"")} -> Eva Martina Casco | B67: 10637796 | C67: {=IFERROR(INDEX(Listado!$C:$C,MATCH($B67,Listado!$B:$B,0)),"")} -> 2257-503835 | D67: {=IFERROR(INDEX(Listado!$D:$D,MATCH($B67,Listado!$B:$B,0)),"")} -> Montevideo 411 | E67: {=IFERROR(INDEX(Listado!$E:$E,MATCH($B67,Listado!$B:$B,0)),"")} -> 2 | F67: {=IFERROR(INDEX(Listado!$F:$F,MATCH($B67,Listado!$B:$B,0)),"")} -> Alicia
A68: {=IFERROR(INDEX(Listado!$A:$A,MATCH($B68,Listado!$B:$B,0)),"")} -> Juan Ramon Podazza | B68: 17067721 | C68: {=IFERROR(INDEX(Listado!$C:$C,MATCH($B68,Listado!$B:$B,0)),"")} -> 2257-524437 | D68: {=IFERROR(INDEX(Listado!$D:$D,MATCH($B68,Listado!$B:$B,0)),"")} -> Espora 2348 | E68: {=IFERROR(INDEX(Listado!$E:$E,MATCH($B68,Listado!$B:$B,0)),"")} -> 4 | F68: {=IFERROR(INDEX(Listado!$F:$F,MATCH($B68,Listado!$B:$B,0)),"")} -> Alicia
A69: {=IFERROR(INDEX(Listado!$A:$A,MATCH($B69,Listado!$B:$B,0)),"")} -> Cristina Yamila Gomez | B69: 37198780 | C69: {=IFERROR(INDEX(Listado!$C:$C,MATCH($B69,Listado!$B:$B,0)),"")} -> 011-53194731 | D69: {=IFERROR(INDEX(Listado!$D:$D,MATCH($B69,Listado!$B:$B,0)),"")} -> Lobo de Mar 905 | E69: {=IFERROR(INDEX(Listado!$E:$E,MATCH($B69,Listado!$B:$B,0)),"")} -> 3 | F69: {=IFERROR(INDEX(Listado!$F:$F,MATCH($B69,Listado!$B:$B,0)),"")} -> Alicia
... A155: {=IFERROR(INDEX(Listado!$A:$A,MATCH($B155,Listado!$B:$B,0)),"")} -> Maria Cristina Figueredo | B155: 94340125 | C155: {=IFERROR(INDEX(Listado!$C:$C,MATCH($B155,Listado!$B:$B,0)),"")} -> 2257-615619 | D155: {=IFERROR(INDEX(Listado!$D:$D,MATCH($B155,Listado!$B:$B,0)),"")} -> Marano 573 | E155: {=IFERROR(INDEX(Listado!$E:$E,MATCH($B155,Listado!$B:$B,0)),"")} -> 2 | F155: {=IFERROR(INDEX(Listado!$F:$F,MATCH($B155,Listado!$B:$B,0)),"")} -> Luciana
...

Sheet Mercadería 250925
A1: NOMBRE Y APELLIDO | B1: DNI | C1: CONTACTO | D1: DIRECCION | E1: COMP. FAMILIAR | F1: RESPONSABLE
A2: {=IFERROR(INDEX(Listado!$A:$A,MATCH($B2,Listado!$B:$B,0)),"")} -> Yamila Daniela Cuevas | B2: 40795111 | C2: {=IFERROR(INDEX(Listado!$C:$C,MATCH($B2,Listado!$B:$B,0)),"")} -> - | D2: {=IFERROR(INDEX(Listado!$D:$D,MATCH($B2,Listado!$B:$B,0)),"")} -> El Ancla y Yunque | E2: {=IFERROR(INDEX(Listado!$E:$E,MATCH($B2,Listado!$B:$B,0)),"")} -> 4 | F2: {=IFERROR(INDEX(Listado!$F:$F,MATCH($B2,Listado!$B:$B,0)),"")} -> Ana
A3: {=IFERROR(INDEX(Listado!$A:$A,MATCH($B3,Listado!$B:$B,0)),"")} -> Melany Fabiana Cuevas | B3: 45914708 | C3: {=IFERROR(INDEX(Listado!$C:$C,MATCH($B3,Listado!$B:$B,0)),"")} -> - | D3: {=IFERROR(INDEX(Listado!$D:$D,MATCH($B3,Listado!$B:$B,0)),"")} -> Julio Campos 1880 | E3: {=IFERROR(INDEX(Listado!$E:$E,MATCH($B3,Listado!$B:$B,0)),"")} -> 3 | F3: {=IFERROR(INDEX(Listado!$F:$F,MATCH($B3,Listado!$B:$B,0)),"")} -> Ana
A4: {=IFERROR(INDEX(Listado!$A:$A,MATCH($B4,Listado!$B:$B,0)),"")} -> Elba Rosa Meneses | B4: 23983063 | C4: {=IFERROR(INDEX(Listado!$C:$C,MATCH($B4,Listado!$B:$B,0)),"")} -> 2257-541106 | D4: {=IFERROR(INDEX(Listado!$D:$D,MATCH($B4,Listado!$B:$B,0)),"")} -> Azopardo 1650 | E4: {=IFERROR(INDEX(Listado!$E:$E,MATCH($B4,Listado!$B:$B,0)),"")} -> 2 | F4: {=IFERROR(INDEX(Listado!$F:$F,MATCH($B4,Listado!$B:$B,0)),"")} -> Ana
A5: {=IFERROR(INDEX(Listado!$A:$A,MATCH($B5,Listado!$B:$B,0)),"")} -> Melany Fabiana Cuevas | B5: 45914708 | C5: {=IFERROR(INDEX(Listado!$C:$C,MATCH($B5,Listado!$B:$B,0)),"")} -> - | D5: {=IFERROR(INDEX(Listado!$D:$D,MATCH($B5,Listado!$B:$B,0)),"")} -> Julio Campos 1880 | E5: {=IFERROR(INDEX(Listado!$E:$E,MATCH($B5,Listado!$B:$B,0)),"")} -> 3 | F5: {=IFERROR(INDEX(Listado!$F:$F,MATCH($B5,Listado!$B:$B,0)),"")} -> Ana
A6: {=IFERROR(INDEX(Listado!$A:$A,MATCH($B6,Listado!$B:$B,0)),"")} -> Luciana Fernanda Cuevas | B6: 43305223 | C6: {=IFERROR(INDEX(Listado!$C:$C,MATCH($B6,Listado!$B:$B,0)),"")} -> - | D6: {=IFERROR(INDEX(Listado!$D:$D,MATCH($B6,Listado!$B:$B,0)),"")} -> Montevideo 2387 | E6: {=IFERROR(INDEX(Listado!$E:$E,MATCH($B6,Listado!$B:$B,0)),"")} -> 3 | F6: {=IFERROR(INDEX(Listado!$F:$F,MATCH($B6,Listado!$B:$B,0)),"")} -> Ana
A7: {=IFERROR(INDEX(Listado!$A:$A,MATCH($B7,Listado!$B:$B,0)),"")} | B7: 12386217 | C7: {=IFERROR(INDEX(Listado!$C:$C,MATCH($B7,Listado!$B:$B,0)),"")} | D7: {=IFERROR(INDEX(Listado!$D:$D,MATCH($B7,Listado!$B:$B,0)),"")} | E7: {=IFERROR(INDEX(Listado!$E:$E,MATCH($B7,Listado!$B:$B,0)),"")} | F7: {=IFERROR(INDEX(Listado!$F:$F,MATCH($B7,Listado!$B:$B,0)),"")}
A8: {=IFERROR(INDEX(Listado!$A:$A,MATCH($B8,Listado!$B:$B,0)),"")} -> Pablo Ariel Agulleiro | B8: 35634360 | C8: {=IFERROR(INDEX(Listado!$C:$C,MATCH($B8,Listado!$B:$B,0)),"")} -> 2257-532967 | D8: {=IFERROR(INDEX(Listado!$D:$D,MATCH($B8,Listado!$B:$B,0)),"")} -> Lugones 1018 | E8: {=IFERROR(INDEX(Listado!$E:$E,MATCH($B8,Listado!$B:$B,0)),"")} -> 4 | F8: {=IFERROR(INDEX(Listado!$F:$F,MATCH($B8,Listado!$B:$B,0)),"")} -> Ana
A9: {=IFERROR(INDEX(Listado!$A:$A,MATCH($B9,Listado!$B:$B,0)),"")} -> Rogelio Batista | B9: 7559612 | C9: {=IFERROR(INDEX(Listado!$C:$C,MATCH($B9,Listado!$B:$B,0)),"")} -> 2257-549977 | D9: {=IFERROR(INDEX(Listado!$D:$D,MATCH($B9,Listado!$B:$B,0)),"")} -> Olmos 509 | E9: {=IFERROR(INDEX(Listado!$E:$E,MATCH($B9,Listado!$B:$B,0)),"")} -> 1 | F9: {=IFERROR(INDEX(Listado!$F:$F,MATCH($B9,Listado!$B:$B,0)),"")} -> Ana
A10: {=IFERROR(INDEX(Listado!$A:$A,MATCH($B10,Listado!$B:$B,0)),"")} -> Gisela Veronica Detomasi | B10: 29986427 | C10: {=IFERROR(INDEX(Listado!$C:$C,MATCH($B10,Listado!$B:$B,0)),"")} -> 2257-547594 | D10: {=IFERROR(INDEX(Listado!$D:$D,MATCH($B10,Listado!$B:$B,0)),"")} -> Marmol 236 | E10: {=IFERROR(INDEX(Listado!$E:$E,MATCH($B10,Listado!$B:$B,0)),"")} -> 4 | F10: {=IFERROR(INDEX(Listado!$F:$F,MATCH($B10,Listado!$B:$B,0)),"")} -> Ana
A11: {=IFERROR(INDEX(Listado!$A:$A,MATCH($B11,Listado!$B:$B,0)),"")} -> Maria Soledad Silva | B11: 38955123 | C11: {=IFERROR(INDEX(Listado!$C:$C,MATCH($B11,Listado!$B:$B,0)),"")} -> 2257-541954 | D11: {=IFERROR(INDEX(Listado!$D:$D,MATCH($B11,Listado!$B:$B,0)),"")} -> Ascasubi 240 | E11: {=IFERROR(INDEX(Listado!$E:$E,MATCH($B11,Listado!$B:$B,0)),"")} -> 5 | F11: {=IFERROR(INDEX(Listado!$F:$F,MATCH($B11,Listado!$B:$B,0)),"")} -> Ana
A12: {=IFERROR(INDEX(Listado!$A:$A,MATCH($B12,Listado!$B:$B,0)),"")} -> Silvia Antonia Matus | B12: 11817522 | C12: {=IFERROR(INDEX(Listado!$C:$C,MATCH($B12,Listado!$B:$B,0)),"")} -> 2122943181 | D12: {=IFERROR(INDEX(Listado!$D:$D,MATCH($B12,Listado!$B:$B,0)),"")} -> Yunque 710 | E12: {=IFERROR(INDEX(Listado!$E:$E,MATCH($B12,Listado!$B:$B,0)),"")} -> 4 | F12: {=IFERROR(INDEX(Listado!$F:$F,MATCH($B12,Listado!$B:$B,0)),"")} -> Ana
A13: {=IFERROR(INDEX(Listado!$A:$A,MATCH($B13,Listado!$B:$B,0)),"")} -> Erica Cristina Urueña | B13: 31135866 | C13: {=IFERROR(INDEX(Listado!$C:$C,MATCH($B13,Listado!$B:$B,0)),"")} -> 2257-700221 | D13: {=IFERROR(INDEX(Listado!$D:$D,MATCH($B13,Listado!$B:$B,0)),"")} -> Castelli 1350 | E13: {=IFERROR(INDEX(Listado!$E:$E,MATCH($B13,Listado!$B:$B,0)),"")} -> 4 | F13: {=IFERROR(INDEX(Listado!$F:$F,MATCH($B13,Listado!$B:$B,0)),"")} -> Ana
... A22: {=IFERROR(INDEX(Listado!$A:$A,MATCH($B22,Listado!$B:$B,0)),"")} -> Yamila Gisel Balmaceda | B22: 34122822 | C22: {=IFERROR(INDEX(Listado!$C:$C,MATCH($B22,Listado!$B:$B,0)),"")} -> -- | D22: {=IFERROR(INDEX(Listado!$D:$D,MATCH($B22,Listado!$B:$B,0)),"")} -> Sacconi 1987 | E22: {=IFERROR(INDEX(Listado!$E:$E,MATCH($B22,Listado!$B:$B,0)),"")} -> 2 | F22: {=IFERROR(INDEX(Listado!$F:$F,MATCH($B22,Listado!$B:$B,0)),"")} -> Elena
A23: Maria de las Mercedes Adauto | B23: 17888282 | C23: {=IFERROR(INDEX(Listado!$C:$C,MATCH($B23,Listado!$B:$B,0)),"")} -> 2257-549204 | D23: {=IFERROR(INDEX(Listado!$D:$D,MATCH($B23,Listado!$B:$B,0)),"")} -> Arrecifes 1583 | E23: {=IFERROR(INDEX(Listado!$E:$E,MATCH($B23,Listado!$B:$B,0)),"")} -> 2 | F23: {=IFERROR(INDEX(Listado!$F:$F,MATCH($B23,Listado!$B:$B,0)),"")} -> Elena
A24: {=IFERROR(INDEX(Listado!$A:$A,MATCH($B24,Listado!$B:$B,0)),"")} -> Maria De Los Angeles Estevez | B24: 27776059 | C24: {=IFERROR(INDEX(Listado!$C:$C,MATCH($B24,Listado!$B:$B,0)),"")} -> 2257-615262 | D24: {=IFERROR(INDEX(Listado!$D:$D,MATCH($B24,Listado!$B:$B,0)),"")} -> La Margarita 197 | E24: {=IFERROR(INDEX(Listado!$E:$E,MATCH($B24,Listado!$B:$B,0)),"")} -> 4 | F24: {=IFERROR(INDEX(Listado!$F:$F,MATCH($B24,Listado!$B:$B,0)),"")} -> Elena
A25: {=IFERROR(INDEX(Listado!$A:$A,MATCH($B25,Listado!$B:$B,0)),"")} -> Veronica Edith Toloza | B25: 30267029 | C25: {=IFERROR(INDEX(Listado!$C:$C,MATCH($B25,Listado!$B:$B,0)),"")} -> 2257-407658 | D25: {=IFERROR(INDEX(Listado!$D:$D,MATCH($B25,Listado!$B:$B,0)),"")} -> Marmol 555 | E25: {=IFERROR(INDEX(Listado!$E:$E,MATCH($B25,Listado!$B:$B,0)),"")} -> 3 | F25: {=IFERROR(INDEX(Listado!$F:$F,MATCH($B25,Listado!$B:$B,0)),"")} -> Elena
A26: {=IFERROR(INDEX(Listado!$A:$A,MATCH($B26,Listado!$B:$B,0)),"")} -> Eunice Monges Martinez | B26: 95095294 | C26: {=IFERROR(INDEX(Listado!$C:$C,MATCH($B26,Listado!$B:$B,0)),"")} -> 011-51785041 | D26: {=IFERROR(INDEX(Listado!$D:$D,MATCH($B26,Listado!$B:$B,0)),"")} -> La Argentina 2186 | E26: {=IFERROR(INDEX(Listado!$E:$E,MATCH($B26,Listado!$B:$B,0)),"")} -> 5 | F26: {=IFERROR(INDEX(Listado!$F:$F,MATCH($B26,Listado!$B:$B,0)),"")} -> Elena
A27: {=IFERROR(INDEX(Listado!$A:$A,MATCH($B27,Listado!$B:$B,0)),"")} -> Mabel Monges Martinez | B27: 95104177 | C27: {=IFERROR(INDEX(Listado!$C:$C,MATCH($B27,Listado!$B:$B,0)),"")} -> 2257-414903 | D27: {=IFERROR(INDEX(Listado!$D:$D,MATCH($B27,Listado!$B:$B,0)),"")} -> Guiraldes 1279 | E27: {=IFERROR(INDEX(Listado!$E:$E,MATCH($B27,Listado!$B:$B,0)),"")} -> 5 | F27: {=IFERROR(INDEX(Listado!$F:$F,MATCH($B27,Listado!$B:$B,0)),"")} -> Elena
A28: {=IFERROR(INDEX(Listado!$A:$A,MATCH($B28,Listado!$B:$B,0)),"")} -> Lucas Enrique Sernagoras | B28: 36525027 | C28: {=IFERROR(INDEX(Listado!$C:$C,MATCH($B28,Listado!$B:$B,0)),"")} -> 2257-307829 | D28: {=IFERROR(INDEX(Listado!$D:$D,MATCH($B28,Listado!$B:$B,0)),"")} -> Termas de Rio Hondo 271 | E28: {=IFERROR(INDEX(Listado!$E:$E,MATCH($B28,Listado!$B:$B,0)),"")} -> 2 | F28: {=IFERROR(INDEX(Listado!$F:$F,MATCH($B28,Listado!$B:$B,0)),"")} -> Elena
A29: {=IFERROR(INDEX(Listado!$A:$A,MATCH($B29,Listado!$B:$B,0)),"")} -> Jorge Osvaldo Garcilazo | B29: 14337753 | C29: {=IFERROR(INDEX(Listado!$C:$C,MATCH($B29,Listado!$B:$B,0)),"")} -> - | D29: {=IFERROR(INDEX(Listado!$D:$D,MATCH($B29,Listado!$B:$B,0)),"")} -> Colon y Palacios | E29: {=IFERROR(INDEX(Listado!$E:$E,MATCH($B29,Listado!$B:$B,0)),"")} -> 1 | F29: {=IFERROR(INDEX(Listado!$F:$F,MATCH($B29,Listado!$B:$B,0)),"")} -> Elena
A30: {=IFERROR(INDEX(Listado!$A:$A,MATCH($B30,Listado!$B:$B,0)),"")} -> Jorge Damian Bongrani | B30: 41258385 | C30: {=IFERROR(INDEX(Listado!$C:$C,MATCH($B30,Listado!$B:$B,0)),"")} -> 2236926007 | D30: {=IFERROR(INDEX(Listado!$D:$D,MATCH($B30,Listado!$B:$B,0)),"")} -> Blanco Encalada (Casa 2) | E30: {=IFERROR(INDEX(Listado!$E:$E,MATCH($B30,Listado!$B:$B,0)),"")} -> 1 | F30: {=IFERROR(INDEX(Listado!$F:$F,MATCH($B30,Listado!$B:$B,0)),"")} -> Elena
A31: {=IFERROR(INDEX(Listado!$A:$A,MATCH($B31,Listado!$B:$B,0)),"")} -> Juan Jose Carrera | B31: 33755466 | C31: {=IFERROR(INDEX(Listado!$C:$C,MATCH($B31,Listado!$B:$B,0)),"")} -> 2257-527228 | D31: {=IFERROR(INDEX(Listado!$D:$D,MATCH($B31,Listado!$B:$B,0)),"")} -> Marano 1053 | E31: {=IFERROR(INDEX(Listado!$E:$E,MATCH($B31,Listado!$B:$B,0)),"")} -> 3 | F31: {=IFERROR(INDEX(Listado!$F:$F,MATCH($B31,Listado!$B:$B,0)),"")} -> Elena
A32: {=IFERROR(INDEX(Listado!$A:$A,MATCH($B32,Listado!$B:$B,0)),"")} -> Ramirez Ariel | B32: 25886613 | C32: {=IFERROR(INDEX(Listado!$C:$C,MATCH($B32,Listado!$B:$B,0)),"")} -> - | D32: {=IFERROR(INDEX(Listado!$D:$D,MATCH($B32,Listado!$B:$B,0)),"")} -> Pueyredon 1540 | E32: {=IFERROR(INDEX(Listado!$E:$E,MATCH($B32,Listado!$B:$B,0)),"")} | F32: {=IFERROR(INDEX(Listado!$F:$F,MATCH($B32,Listado!$B:$B,0)),"")} -> Elena
A33: {=IFERROR(INDEX(Listado!$A:$A,MATCH($B33,Listado!$B:$B,0)),"")} -> Yamila Gisel Balmaceda | B33: 34122822 | C33: - | D33: {=IFERROR(INDEX(Listado!$D:$D,MATCH($B33,Listado!$B:$B,0)),"")} -> Sacconi 1987 | E33: {=IFERROR(INDEX(Listado!$E:$E,MATCH($B33,Listado!$B:$B,0)),"")} -> 2 | F33: {=IFERROR(INDEX(Listado!$F:$F,MATCH($B33,Listado!$B:$B,0)),"")} -> Elena
A34: {=IFERROR(INDEX(Listado!$A:$A,MATCH($B34,Listado!$B:$B,0)),"")} -> Cavallear Monica | B34: 35202893 | C34: {=IFERROR(INDEX(Listado!$C:$C,MATCH($B34,Listado!$B:$B,0)),"")} -> - | D34: {=IFERROR(INDEX(Listado!$D:$D,MATCH($B34,Listado!$B:$B,0)),"")} -> Saconi 1612 | E34: {=IFERROR(INDEX(Listado!$E:$E,MATCH($B34,Listado!$B:$B,0)),"")} | F34: {=IFERROR(INDEX(Listado!$F:$F,MATCH($B34,Listado!$B:$B,0)),"")} -> Elena
A35: {=IFERROR(INDEX(Listado!$A:$A,MATCH($B35,Listado!$B:$B,0)),"")} -> Pabla Martinez Silvero | B35: 92148168 | C35: {=IFERROR(INDEX(Listado!$C:$C,MATCH($B35,Listado!$B:$B,0)),"")} -> 011-63508544 | D35: {=IFERROR(INDEX(Listado!$D:$D,MATCH($B35,Listado!$B:$B,0)),"")} -> Magallanes 1487 | E35: {=IFERROR(INDEX(Listado!$E:$E,MATCH($B35,Listado!$B:$B,0)),"")} -> 1 | F35: {=IFERROR(INDEX(Listado!$F:$F,MATCH($B35,Listado!$B:$B,0)),"")} -> Silvia
A36: {=IFERROR(INDEX(Listado!$A:$A,MATCH($B36,Listado!$B:$B,0)),"")} -> Noelia Arcelus | B36: 25762854 | C36: {=IFERROR(INDEX(Listado!$C:$C,MATCH($B36,Listado!$B:$B,0)),"")} -> - | D36: {=IFERROR(INDEX(Listado!$D:$D,MATCH($B36,Listado!$B:$B,0)),"")} -> - | E36: {=IFERROR(INDEX(Listado!$E:$E,MATCH($B36,Listado!$B:$B,0)),"")} -> - | F36: {=IFERROR(INDEX(Listado!$F:$F,MATCH($B36,Listado!$B:$B,0)),"")} -> Elena
A37: {=IFERROR(INDEX(Listado!$A:$A,MATCH($B37,Listado!$B:$B,0)),"")} -> Rojas Maidana Ludmila Milagros Aylen | B37: 48035627 | C37: {=IFERROR(INDEX(Listado!$C:$C,MATCH($B37,Listado!$B:$B,0)),"")} -> - | D37: {=IFERROR(INDEX(Listado!$D:$D,MATCH($B37,Listado!$B:$B,0)),"")} -> Margarita 750 | E37: {=IFERROR(INDEX(Listado!$E:$E,MATCH($B37,Listado!$B:$B,0)),"")} | F37: {=IFERROR(INDEX(Listado!$F:$F,MATCH($B37,Listado!$B:$B,0)),"")} -> Elena
A38: {=IFERROR(INDEX(Listado!$A:$A,MATCH($B38,Listado!$B:$B,0)),"")} -> Rivero Maria Celeste | B38: 36825520 | C38: {=IFERROR(INDEX(Listado!$C:$C,MATCH($B38,Listado!$B:$B,0)),"")} -> - | D38: {=IFERROR(INDEX(Listado!$D:$D,MATCH($B38,Listado!$B:$B,0)),"")} -> Lobo de Mar 136 | E38: {=IFERROR(INDEX(Listado!$E:$E,MATCH($B38,Listado!$B:$B,0)),"")} | F38: {=IFERROR(INDEX(Listado!$F:$F,MATCH($B38,Listado!$B:$B,0)),"")} -> Elena
A39: {=IFERROR(INDEX(Listado!$A:$A,MATCH($B39,Listado!$B:$B,0)),"")} -> Leila Daiana Barrionuevo | B39: 41196195 | C39: {=IFERROR(INDEX(Listado!$C:$C,MATCH($B39,Listado!$B:$B,0)),"")} -> 2257-558726 | D39: {=IFERROR(INDEX(Listado!$D:$D,MATCH($B39,Listado!$B:$B,0)),"")} -> Blanco Encalada 2281 | E39: {=IFERROR(INDEX(Listado!$E:$E,MATCH($B39,Listado!$B:$B,0)),"")} -> 3 | F39: {=IFERROR(INDEX(Listado!$F:$F,MATCH($B39,Listado!$B:$B,0)),"")} -> Alicia
A40: {=IFERROR(INDEX(Listado!$A:$A,MATCH($B40,Listado!$B:$B,0)),"")} -> Santa Cecilia Gularte | B40: 30792577 | C40: {=IFERROR(INDEX(Listado!$C:$C,MATCH($B40,Listado!$B:$B,0)),"")} -> 2257-417827 | D40: {=IFERROR(INDEX(Listado!$D:$D,MATCH($B40,Listado!$B:$B,0)),"")} -> Ascasubi 589 | E40: {=IFERROR(INDEX(Listado!$E:$E,MATCH($B40,Listado!$B:$B,0)),"")} -> 6 | F40: {=IFERROR(INDEX(Listado!$F:$F,MATCH($B40,Listado!$B:$B,0)),"")} -> Alicia
A41: {=IFERROR(INDEX(Listado!$A:$A,MATCH($B41,Listado!$B:$B,0)),"")} -> Laura Andrea Troncoso | B41: 31885659 | C41: {=IFERROR(INDEX(Listado!$C:$C,MATCH($B41,Listado!$B:$B,0)),"")} -> 2257-761587 | D41: {=IFERROR(INDEX(Listado!$D:$D,MATCH($B41,Listado!$B:$B,0)),"")} -> Marejada y Montevideo | E41: {=IFERROR(INDEX(Listado!$E:$E,MATCH($B41,Listado!$B:$B,0)),"")} -> 5 | F41: {=IFERROR(INDEX(Listado!$F:$F,MATCH($B41,Listado!$B:$B,0)),"")} -> Romina
A42: {=IFERROR(INDEX(Listado!$A:$A,MATCH($B42,Listado!$B:$B,0)),"")} -> Lucy Suarez | B42: 2362837 | C42: {=IFERROR(INDEX(Listado!$C:$C,MATCH($B42,Listado!$B:$B,0)),"")} | D42: {=IFERROR(INDEX(Listado!$D:$D,MATCH($B42,Listado!$B:$B,0)),"")} -> Quinteros 954 | E42: {=IFERROR(INDEX(Listado!$E:$E,MATCH($B42,Listado!$B:$B,0)),"")} | F42: {=IFERROR(INDEX(Listado!$F:$F,MATCH($B42,Listado!$B:$B,0)),"")} -> Romina
A43: {=IFERROR(INDEX(Listado!$A:$A,MATCH($B43,Listado!$B:$B,0)),"")} -> Margot Aurora Rodriguez | B43: 13186317 | C43: {=IFERROR(INDEX(Listado!$C:$C,MATCH($B43,Listado!$B:$B,0)),"")} -> 2257-520785 | D43: {=IFERROR(INDEX(Listado!$D:$D,MATCH($B43,Listado!$B:$B,0)),"")} -> Espora 1055 | E43: {=IFERROR(INDEX(Listado!$E:$E,MATCH($B43,Listado!$B:$B,0)),"")} -> 1 | F43: {=IFERROR(INDEX(Listado!$F:$F,MATCH($B43,Listado!$B:$B,0)),"")} -> Romina
A44: {=IFERROR(INDEX(Listado!$A:$A,MATCH($B44,Listado!$B:$B,0)),"")} -> Silvina Zalazar | B44: 30304758 | C44: {=IFERROR(INDEX(Listado!$C:$C,MATCH($B44,Listado!$B:$B,0)),"")} -> 2257-541249 | D44: {=IFERROR(INDEX(Listado!$D:$D,MATCH($B44,Listado!$B:$B,0)),"")} -> Marmol (Casa 2) | E44: {=IFERROR(INDEX(Listado!$E:$E,MATCH($B44,Listado!$B:$B,0)),"")} -> 4 | F44: {=IFERROR(INDEX(Listado!$F:$F,MATCH($B44,Listado!$B:$B,0)),"")} -> Romina
A45: {=IFERROR(INDEX(Listado!$A:$A,MATCH($B45,Listado!$B:$B,0)),"")} -> Marta Alicia Roldan | B45: 6283445 | C45: {=IFERROR(INDEX(Listado!$C:$C,MATCH($B45,Listado!$B:$B,0)),"")} -> 2257-610397 | D45: {=IFERROR(INDEX(Listado!$D:$D,MATCH($B45,Listado!$B:$B,0)),"")} -> Cramer 595 | E45: {=IFERROR(INDEX(Listado!$E:$E,MATCH($B45,Listado!$B:$B,0)),"")} -> 2 | F45: {=IFERROR(INDEX(Listado!$F:$F,MATCH($B45,Listado!$B:$B,0)),"")} -> Romina
... A52: {=IFERROR(INDEX(Listado!$A:$A,MATCH($B52,Listado!$B:$B,0)),"")} -> Dora Funes | B52: 27283186 | C52: {=IFERROR(INDEX(Listado!$C:$C,MATCH($B52,Listado!$B:$B,0)),"")} -> 2257-408408 | D52: {=IFERROR(INDEX(Listado!$D:$D,MATCH($B52,Listado!$B:$B,0)),"")} -> Caseros 150 | E52: {=IFERROR(INDEX(Listado!$E:$E,MATCH($B52,Listado!$B:$B,0)),"")} -> 4 | F52: {=IFERROR(INDEX(Listado!$F:$F,MATCH($B52,Listado!$B:$B,0)),"")} -> Alicia
A53: Funes Pablo | C53: - | D53: Hernandez 665 | E53: {=IFERROR(INDEX(Listado!$E:$E,MATCH($B53,Listado!$B:$B,0)),"")} | F53: Alicia
A54: {=IFERROR(INDEX(Listado!$A:$A,MATCH($B54,Listado!$B:$B,0)),"")} -> Irupé Alejandra Chaparro | B54: 40256430 | C54: {=IFERROR(INDEX(Listado!$C:$C,MATCH($B54,Listado!$B:$B,0)),"")} -> 2257-550465 | D54: {=IFERROR(INDEX(Listado!$D:$D,MATCH($B54,Listado!$B:$B,0)),"")} -> Olmos y Pueyrredon (Casa 3) | E54: {=IFERROR(INDEX(Listado!$E:$E,MATCH($B54,Listado!$B:$B,0)),"")} -> 3 | F54: {=IFERROR(INDEX(Listado!$F:$F,MATCH($B54,Listado!$B:$B,0)),"")} -> Alicia
...

Sheet Mercadería 130825 
A1: NOMBRE Y APELLIDO | B1: DNI | C1: CONTACTO | D1: DIRECCION | E1: COMP. FAMILIAR | F1: RESPONSABLE
A2: {=IFERROR(INDEX(Listado!$A:$A,MATCH($B2,Listado!$B:$B,0)),"")} -> Javier Caeta | B2: 16105512 | C2: - | D2: {=IFERROR(INDEX(Listado!$D:$D,MATCH($B2,Listado!$B:$B,0)),"")} -> Pueyrredon 550 | E2: {=IFERROR(INDEX(Listado!$E:$E,MATCH($B2,Listado!$B:$B,0)),"")} -> 1 | F2: {=IFERROR(INDEX(Listado!$F:$F,MATCH($B2,Listado!$B:$B,0)),"")} -> Sandra
A3: {=IFERROR(INDEX(Listado!$A:$A,MATCH($B3,Listado!$B:$B,0)),"")} -> Mabel Mamani | B3: 17081720 | C3: {=IFERROR(INDEX(Listado!$C:$C,MATCH($B3,Listado!$B:$B,0)),"")} -> - | D3: {=IFERROR(INDEX(Listado!$D:$D,MATCH($B3,Listado!$B:$B,0)),"")} -> Salta 2465 | E3: {=IFERROR(INDEX(Listado!$E:$E,MATCH($B3,Listado!$B:$B,0)),"")} -> 4 | F3: {=IFERROR(INDEX(Listado!$F:$F,MATCH($B3,Listado!$B:$B,0)),"")} -> Monica
A4: {=IFERROR(INDEX(Listado!$A:$A,MATCH($B4,Listado!$B:$B,0)),"")} -> Sandra Espindola | B4: 94718024 | C4: {=IFERROR(INDEX(Listado!$C:$C,MATCH($B4,Listado!$B:$B,0)),"")} -> 2257-537826 | D4: {=IFERROR(INDEX(Listado!$D:$D,MATCH($B4,Listado!$B:$B,0)),"")} -> Chascomus 698 | E4: {=IFERROR(INDEX(Listado!$E:$E,MATCH($B4,Listado!$B:$B,0)),"")} -> 4 | F4: {=IFERROR(INDEX(Listado!$F:$F,MATCH($B4,Listado!$B:$B,0)),"")} -> Victoria
A5: {=IFERROR(INDEX(Listado!$A:$A,MATCH($B5,Listado!$B:$B,0)),"")} | B5: 46632105 | C5: {=IFERROR(INDEX(Listado!$C:$C,MATCH($B5,Listado!$B:$B,0)),"")} | D5: {=IFERROR(INDEX(Listado!$D:$D,MATCH($B5,Listado!$B:$B,0)),"")} | E5: {=IFERROR(INDEX(Listado!$E:$E,MATCH($B5,Listado!$B:$B,0)),"")} | F5: {=IFERROR(INDEX(Listado!$F:$F,MATCH($B5,Listado!$B:$B,0)),"")}
A6: {=IFERROR(INDEX(Listado!$A:$A,MATCH($B6,Listado!$B:$B,0)),"")} -> Denis Moyano | B6: 40302862 | C6: {=IFERROR(INDEX(Listado!$C:$C,MATCH($B6,Listado!$B:$B,0)),"")} -> 2257-408408 | D6: {=IFERROR(INDEX(Listado!$D:$D,MATCH($B6,Listado!$B:$B,0)),"")} -> Ramos Mejia 2434 | E6: {=IFERROR(INDEX(Listado!$E:$E,MATCH($B6,Listado!$B:$B,0)),"")} -> 3 | F6: {=IFERROR(INDEX(Listado!$F:$F,MATCH($B6,Listado!$B:$B,0)),"")} -> Alicia
A7: {=IFERROR(INDEX(Listado!$A:$A,MATCH($B7,Listado!$B:$B,0)),"")} -> Dora Funes | B7: 27283186 | C7: {=IFERROR(INDEX(Listado!$C:$C,MATCH($B7,Listado!$B:$B,0)),"")} -> 2257-408408 | D7: {=IFERROR(INDEX(Listado!$D:$D,MATCH($B7,Listado!$B:$B,0)),"")} -> Caseros 150 | E7: {=IFERROR(INDEX(Listado!$E:$E,MATCH($B7,Listado!$B:$B,0)),"")} -> 4 | F7: {=IFERROR(INDEX(Listado!$F:$F,MATCH($B7,Listado!$B:$B,0)),"")} -> Alicia
A8: {=IFERROR(INDEX(Listado!$A:$A,MATCH($B8,Listado!$B:$B,0)),"")} -> Marcela Blanco | B8: 33342388 | C8: {=IFERROR(INDEX(Listado!$C:$C,MATCH($B8,Listado!$B:$B,0)),"")} -> 2257-599517 | D8: {=IFERROR(INDEX(Listado!$D:$D,MATCH($B8,Listado!$B:$B,0)),"")} -> Pueyrredon 1435 | E8: {=IFERROR(INDEX(Listado!$E:$E,MATCH($B8,Listado!$B:$B,0)),"")} -> 8 | F8: {=IFERROR(INDEX(Listado!$F:$F,MATCH($B8,Listado!$B:$B,0)),"")} -> Angeles
A9: {=IFERROR(INDEX(Listado!$A:$A,MATCH($B9,Listado!$B:$B,0)),"")} -> Mara Alexandra Jaimez | B9: 40753683 | C9: {=IFERROR(INDEX(Listado!$C:$C,MATCH($B9,Listado!$B:$B,0)),"")} -> 11-44048500 | D9: {=IFERROR(INDEX(Listado!$D:$D,MATCH($B9,Listado!$B:$B,0)),"")} -> Caseros 1452 | E9: {=IFERROR(INDEX(Listado!$E:$E,MATCH($B9,Listado!$B:$B,0)),"")} -> 2 | F9: {=IFERROR(INDEX(Listado!$F:$F,MATCH($B9,Listado!$B:$B,0)),"")} -> Luciana
A10: {=IFERROR(INDEX(Listado!$A:$A,MATCH($B10,Listado!$B:$B,0)),"")} -> Valor Penolope | B10: 40236566 | C10: {=IFERROR(INDEX(Listado!$C:$C,MATCH($B10,Listado!$B:$B,0)),"")} -> 2257-602744 | D10: {=IFERROR(INDEX(Listado!$D:$D,MATCH($B10,Listado!$B:$B,0)),"")} -> La margarita 785 | E10: {=IFERROR(INDEX(Listado!$E:$E,MATCH($B10,Listado!$B:$B,0)),"")} -> 2 | F10: {=IFERROR(INDEX(Listado!$F:$F,MATCH($B10,Listado!$B:$B,0)),"")} -> Fabian
A11: {=IFERROR(INDEX(Listado!$A:$A,MATCH($B11,Listado!$B:$B,0)),"")} -> Norma Macias | B11: 21976459 | C11: {=IFERROR(INDEX(Listado!$C:$C,MATCH($B11,Listado!$B:$B,0)),"")} -> 011-24603441 | D11: {=IFERROR(INDEX(Listado!$D:$D,MATCH($B11,Listado!$B:$B,0)),"")} -> Libres del Sur 308 | E11: {=IFERROR(INDEX(Listado!$E:$E,MATCH($B11,Listado!$B:$B,0)),"")} -> 2 | F11: {=IFERROR(INDEX(Listado!$F:$F,MATCH($B11,Listado!$B:$B,0)),"")} -> Angeles
A12: {=IFERROR(INDEX(Listado!$A:$A,MATCH($B12,Listado!$B:$B,0)),"")} -> Mauro Natalia | B12: 23847108 | C12: {=IFERROR(INDEX(Listado!$C:$C,MATCH($B12,Listado!$B:$B,0)),"")} -> 11-65421852 | D12: {=IFERROR(INDEX(Listado!$D:$D,MATCH($B12,Listado!$B:$B,0)),"")} -> Fco. Carreras 3367 | E12: {=IFERROR(INDEX(Listado!$E:$E,MATCH($B12,Listado!$B:$B,0)),"")} -> 1 | F12: {=IFERROR(INDEX(Listado!$F:$F,MATCH($B12,Listado!$B:$B,0)),"")} -> Fabian
A13: {=IFERROR(INDEX(Listado!$A:$A,MATCH($B13,Listado!$B:$B,0)),"")} | B13: 40978001 | C13: {=IFERROR(INDEX(Listado!$C:$C,MATCH($B13,Listado!$B:$B,0)),"")} | D13: {=IFERROR(INDEX(Listado!$D:$D,MATCH($B13,Listado!$B:$B,0)),"")} | E13: {=IFERROR(INDEX(Listado!$E:$E,MATCH($B13,Listado!$B:$B,0)),"")} | F13: {=IFERROR(INDEX(Listado!$F:$F,MATCH($B13,Listado!$B:$B,0)),"")}
A14: {=IFERROR(INDEX(Listado!$A:$A,MATCH($B14,Listado!$B:$B,0)),"")} -> Marta Mirta Carrizo | B14: 6168171 | C14: {=IFERROR(INDEX(Listado!$C:$C,MATCH($B14,Listado!$B:$B,0)),"")} -> 2257-660736 | D14: {=IFERROR(INDEX(Listado!$D:$D,MATCH($B14,Listado!$B:$B,0)),"")} -> Olmos y Pueyrredon 15 (Casa 15) | E14: {=IFERROR(INDEX(Listado!$E:$E,MATCH($B14,Listado!$B:$B,0)),"")} -> 5 | F14: {=IFERROR(INDEX(Listado!$F:$F,MATCH($B14,Listado!$B:$B,0)),"")} -> Elena
... A121: {=IFERROR(INDEX(Listado!$A:$A,MATCH($B121,Listado!$B:$B,0)),"")} -> Eliana Anahi Rodriguez | B121: 33329437 | C121: {=IFERROR(INDEX(Listado!$C:$C,MATCH($B121,Listado!$B:$B,0)),"")} -> 2257-544422 | D121: {=IFERROR(INDEX(Listado!$D:$D,MATCH($B121,Listado!$B:$B,0)),"")} -> Saconi 1844 | E121: {=IFERROR(INDEX(Listado!$E:$E,MATCH($B121,Listado!$B:$B,0)),"")} -> 3 | F121: {=IFERROR(INDEX(Listado!$F:$F,MATCH($B121,Listado!$B:$B,0)),"")} -> Silvia
A122: Martinez Brenda | B122: 41876296 | C122: 2257-500605 | D122: El Ancla 368 | E122: 5 | F122: Lucia
A123: Lucas Herrera | B123: 44240887 | C123: 2257-412324 | D123: Ascasubi 570 | E123: 3 | F123: Victoria
A124: {=IFERROR(INDEX(Listado!$A:$A,MATCH($B124,Listado!$B:$B,0)),"")} -> Ubiedo Erica Roxana | B124: 40256354 | C124: {=IFERROR(INDEX(Listado!$C:$C,MATCH($B124,Listado!$B:$B,0)),"")} -> 2257669405 | D124: {=IFERROR(INDEX(Listado!$D:$D,MATCH($B124,Listado!$B:$B,0)),"")} -> Los Andes 2078 (Casa 2) | E124: {=IFERROR(INDEX(Listado!$E:$E,MATCH($B124,Listado!$B:$B,0)),"")} -> 4 | F124: {=IFERROR(INDEX(Listado!$F:$F,MATCH($B124,Listado!$B:$B,0)),"")} -> Tamara
A125: {=IFERROR(INDEX(Listado!$A:$A,MATCH($B125,Listado!$B:$B,0)),"")} -> Sarmiento Claudio | B125: 45519987 | C125: {=IFERROR(INDEX(Listado!$C:$C,MATCH($B125,Listado!$B:$B,0)),"")} -> 2257556005 | D125: {=IFERROR(INDEX(Listado!$D:$D,MATCH($B125,Listado!$B:$B,0)),"")} -> Los Andes 2078 (Casa 1) | E125: {=IFERROR(INDEX(Listado!$E:$E,MATCH($B125,Listado!$B:$B,0)),"")} -> 4 | F125: {=IFERROR(INDEX(Listado!$F:$F,MATCH($B125,Listado!$B:$B,0)),"")} -> Tamara
A126: {=IFERROR(INDEX(Listado!$A:$A,MATCH($B126,Listado!$B:$B,0)),"")} -> Mariana Cabrera | B126: 44520581 | C126: {=IFERROR(INDEX(Listado!$C:$C,MATCH($B126,Listado!$B:$B,0)),"")} -> 2257-552145 | D126: {=IFERROR(INDEX(Listado!$D:$D,MATCH($B126,Listado!$B:$B,0)),"")} -> Chascomus 698 | E126: {=IFERROR(INDEX(Listado!$E:$E,MATCH($B126,Listado!$B:$B,0)),"")} -> 2 | F126: {=IFERROR(INDEX(Listado!$F:$F,MATCH($B126,Listado!$B:$B,0)),"")} -> Luciana
A127: {=IFERROR(INDEX(Listado!$A:$A,MATCH($B127,Listado!$B:$B,0)),"")} -> Barragan Analia Elizabeth | B127: 29211601 | C127: {=IFERROR(INDEX(Listado!$C:$C,MATCH($B127,Listado!$B:$B,0)),"")} -> 2257-637852 | D127: {=IFERROR(INDEX(Listado!$D:$D,MATCH($B127,Listado!$B:$B,0)),"")} -> montevideo 1455 | E127: {=IFERROR(INDEX(Listado!$E:$E,MATCH($B127,Listado!$B:$B,0)),"")} -> 2 | F127: {=IFERROR(INDEX(Listado!$F:$F,MATCH($B127,Listado!$B:$B,0)),"")} -> Fabian
A128: {=IFERROR(INDEX(Listado!$A:$A,MATCH($B128,Listado!$B:$B,0)),"")} -> Camila Zieziulewicz | B128: 39066542 | C128: {=IFERROR(INDEX(Listado!$C:$C,MATCH($B128,Listado!$B:$B,0)),"")} -> - | D128: {=IFERROR(INDEX(Listado!$D:$D,MATCH($B128,Listado!$B:$B,0)),"")} -> Lugones 402 | E128: {=IFERROR(INDEX(Listado!$E:$E,MATCH($B128,Listado!$B:$B,0)),"")} -> 4 | F128: {=IFERROR(INDEX(Listado!$F:$F,MATCH($B128,Listado!$B:$B,0)),"")} -> Monica
A129: Galarza Isabel | B129: 26935088 | C129: 2257-602669 | D129: Fco. Carreras 1727 | E129: 2 | F129: {=IFERROR(INDEX(Listado!$F:$F,MATCH($B129,Listado!$B:$B,0)),"")} -> Monica
A130: {=IFERROR(INDEX(Listado!$A:$A,MATCH($B130,Listado!$B:$B,0)),"")} -> Cabrera Myrna Solange | B130: 35085143 | C130: {=IFERROR(INDEX(Listado!$C:$C,MATCH($B130,Listado!$B:$B,0)),"")} -> 1173685154 | D130: {=IFERROR(INDEX(Listado!$D:$D,MATCH($B130,Listado!$B:$B,0)),"")} -> Gaboto 2123 | E130: {=IFERROR(INDEX(Listado!$E:$E,MATCH($B130,Listado!$B:$B,0)),"")} -> 6 | F130: {=IFERROR(INDEX(Listado!$F:$F,MATCH($B130,Listado!$B:$B,0)),"")} -> Tamara
A131: {=IFERROR(INDEX(Listado!$A:$A,MATCH($B131,Listado!$B:$B,0)),"")} -> Barzala Felicia | B131: 42762556 | C131: {=IFERROR(INDEX(Listado!$C:$C,MATCH($B131,Listado!$B:$B,0)),"")} -> 2254423261 | D131: {=IFERROR(INDEX(Listado!$D:$D,MATCH($B131,Listado!$B:$B,0)),"")} -> Santiago del Estero y Falkner | E131: {=IFERROR(INDEX(Listado!$E:$E,MATCH($B131,Listado!$B:$B,0)),"")} -> 4 | F131: {=IFERROR(INDEX(Listado!$F:$F,MATCH($B131,Listado!$B:$B,0)),"")} -> Tamara
A132: {=IFERROR(INDEX(Listado!$A:$A,MATCH($B132,Listado!$B:$B,0)),"")} -> Victor Emanuel Montenegro | B132: 39151179 | C132: {=IFERROR(INDEX(Listado!$C:$C,MATCH($B132,Listado!$B:$B,0)),"")} -> - | D132: {=IFERROR(INDEX(Listado!$D:$D,MATCH($B132,Listado!$B:$B,0)),"")} -> El Ancla 1447 | E132: {=IFERROR(INDEX(Listado!$E:$E,MATCH($B132,Listado!$B:$B,0)),"")} -> 4 | F132: {=IFERROR(INDEX(Listado!$F:$F,MATCH($B132,Listado!$B:$B,0)),"")} -> Marcia
A133: {=IFERROR(INDEX(Listado!$A:$A,MATCH($B133,Listado!$B:$B,0)),"")} -> Wilma Villalba Ledezma | B133: 94586975 | C133: {=IFERROR(INDEX(Listado!$C:$C,MATCH($B133,Listado!$B:$B,0)),"")} -> 2257-555383 | D133: {=IFERROR(INDEX(Listado!$D:$D,MATCH($B133,Listado!$B:$B,0)),"")} -> Madariaga 1250 | E133: {=IFERROR(INDEX(Listado!$E:$E,MATCH($B133,Listado!$B:$B,0)),"")} -> 4 | F133: {=IFERROR(INDEX(Listado!$F:$F,MATCH($B133,Listado!$B:$B,0)),"")} -> Luciana
A134: {=IFERROR(INDEX(Listado!$A:$A,MATCH($B134,Listado!$B:$B,0)),"")} -> Vivas Celeste | B134: 42622757 | C134: {=IFERROR(INDEX(Listado!$C:$C,MATCH($B134,Listado!$B:$B,0)),"")} -> 2257683358 | D134: {=IFERROR(INDEX(Listado!$D:$D,MATCH($B134,Listado!$B:$B,0)),"")} -> Marano 1477 | E134: {=IFERROR(INDEX(Listado!$E:$E,MATCH($B134,Listado!$B:$B,0)),"")} -> 3 | F134: {=IFERROR(INDEX(Listado!$F:$F,MATCH($B134,Listado!$B:$B,0)),"")} -> Tamara
A135: {=IFERROR(INDEX(Listado!$A:$A,MATCH($B135,Listado!$B:$B,0)),"")} -> Ortiz Natalia | B135: 33738927 | C135: {=IFERROR(INDEX(Listado!$C:$C,MATCH($B135,Listado!$B:$B,0)),"")} -> 2257556242 | D135: {=IFERROR(INDEX(Listado!$D:$D,MATCH($B135,Listado!$B:$B,0)),"")} -> Lebenson 554 | E135: {=IFERROR(INDEX(Listado!$E:$E,MATCH($B135,Listado!$B:$B,0)),"")} -> 3 | F135: {=IFERROR(INDEX(Listado!$F:$F,MATCH($B135,Listado!$B:$B,0)),"")} -> Sofia
A136: Meccia Ruben | B136: 307639 | C136: 2257-523162 | D136: Dolores 620 | E136: 2 | F136: Romina
A137: Aureliana Rodriguez | B137: 94335000 | C137: -- | D137: Dolores 620 | E137: 4 | F137: Romina
A138: Castro Amelia | B138: 11730352 | C138: 2257-648751 | D138: Olmos 234 | E138: 1 | F138: Alicia
A139: Sol Hernaga | B139: 44426722 | C139: 2257-400975 | D139: Lobo del Mar 895 | E139: 6 | F139: Luciana
A140: {=IFERROR(INDEX(Listado!$A:$A,MATCH($B140,Listado!$B:$B,0)),"")} -> Juan Ramon Podazza | B140: 17067721 | C140: {=IFERROR(INDEX(Listado!$C:$C,MATCH($B140,Listado!$B:$B,0)),"")} -> 2257-524437 | D140: {=IFERROR(INDEX(Listado!$D:$D,MATCH($B140,Listado!$B:$B,0)),"")} -> Espora 2348 | E140: {=IFERROR(INDEX(Listado!$E:$E,MATCH($B140,Listado!$B:$B,0)),"")} -> 4 | F140: {=IFERROR(INDEX(Listado!$F:$F,MATCH($B140,Listado!$B:$B,0)),"")} -> Alicia
A141: Lopes Julio | B141: 94970030 | C141: 221-6763294 | D141: Solis 1834 | E141: 2 | F141: Victoria
A142: {=IFERROR(INDEX(Listado!$A:$A,MATCH($B142,Listado!$B:$B,0)),"")} -> Maria del Carmen Mendieta | B142: 22731651 | C142: {=IFERROR(INDEX(Listado!$C:$C,MATCH($B142,Listado!$B:$B,0)),"")} -> 2257-410948 | D142: {=IFERROR(INDEX(Listado!$D:$D,MATCH($B142,Listado!$B:$B,0)),"")} -> Alberdi 1450 | E142: {=IFERROR(INDEX(Listado!$E:$E,MATCH($B142,Listado!$B:$B,0)),"")} -> 4 | F142: {=IFERROR(INDEX(Listado!$F:$F,MATCH($B142,Listado!$B:$B,0)),"")} -> Laura
A143: Aranda Ramon | B143: 5312601 | C143: -- | D143: Olmos 290 | E143: 1 | F143: Alicia
A144: {=IFERROR(INDEX(Listado!$A:$A,MATCH($B144,Listado!$B:$B,0)),"")} -> Lautaro Antonio Nieves Odriozola | B144: 47088131 | C144: {=IFERROR(INDEX(Listado!$C:$C,MATCH($B144,Listado!$B:$B,0)),"")} -> 2257-543067 | D144: {=IFERROR(INDEX(Listado!$D:$D,MATCH($B144,Listado!$B:$B,0)),"")} -> Querini y el Cano (Casa 70) | E144: {=IFERROR(INDEX(Listado!$E:$E,MATCH($B144,Listado!$B:$B,0)),"")} -> 2 | F144: {=IFERROR(INDEX(Listado!$F:$F,MATCH($B144,Listado!$B:$B,0)),"")} -> Ana
A145: Blanco Fernando | B145: 31885815 | C145: 2257-555319 | D145: Querini casa 31 | E145: 5 | F145: Elena
A146: {=IFERROR(INDEX(Listado!$A:$A,MATCH($B146,Listado!$B:$B,0)),"")} -> Nancy Mabel Navia | B146: 33797540 | C146: {=IFERROR(INDEX(Listado!$C:$C,MATCH($B146,Listado!$B:$B,0)),"")} -> 2257-15556874 | D146: {=IFERROR(INDEX(Listado!$D:$D,MATCH($B146,Listado!$B:$B,0)),"")} -> Tierra del Fuego 1966 | E146: 7 | F146: {=IFERROR(INDEX(Listado!$F:$F,MATCH($B146,Listado!$B:$B,0)),"")} -> Monica
...

Sheet Mercaderìa 060426
A1: FAMILIA | B1: DNI | C1: CONTACTO | D1: DIRECCIÓN | E1: COMP. FAMILIAR | F1: RESPONSABLE
A2: {=IFERROR(INDEX(Listado!$A:$A,MATCH($B2,Listado!$B:$B,0)),"")} -> Ruiz Mónica | B2: 27290985 | C2: {=IFERROR(INDEX(Listado!$C:$C,MATCH($B2,Listado!$B:$B,0)),"")} -> 3413867020 | D2: {=IFERROR(INDEX(Listado!$D:$D,MATCH($B2,Listado!$B:$B,0)),"")} -> Margarita 803 | E2: {=IFERROR(INDEX(Listado!$E:$E,MATCH($B2,Listado!$B:$B,0)),"")} -> 4 | F2: {=IFERROR(INDEX(Listado!$F:$F,MATCH($B2,Listado!$B:$B,0)),"")} -> Sofia
A3: {=IFERROR(INDEX(Listado!$A:$A,MATCH($B3,Listado!$B:$B,0)),"")} -> Astudillo Monica | B3: 22062231 | C3: {=IFERROR(INDEX(Listado!$C:$C,MATCH($B3,Listado!$B:$B,0)),"")} -> 2257667914 | D3: {=IFERROR(INDEX(Listado!$D:$D,MATCH($B3,Listado!$B:$B,0)),"")} -> Marejada 180 | E3: {=IFERROR(INDEX(Listado!$E:$E,MATCH($B3,Listado!$B:$B,0)),"")} -> 5 | F3: {=IFERROR(INDEX(Listado!$F:$F,MATCH($B3,Listado!$B:$B,0)),"")} -> Sofia
A4: {=IFERROR(INDEX(Listado!$A:$A,MATCH($B4,Listado!$B:$B,0)),"")} -> Blanca Gonzalez | B4: 94927871 | C4: {=IFERROR(INDEX(Listado!$C:$C,MATCH($B4,Listado!$B:$B,0)),"")} -> 2257313577 | D4: {=IFERROR(INDEX(Listado!$D:$D,MATCH($B4,Listado!$B:$B,0)),"")} -> Argentina 2186 | E4: {=IFERROR(INDEX(Listado!$E:$E,MATCH($B4,Listado!$B:$B,0)),"")} -> 4 | F4: {=IFERROR(INDEX(Listado!$F:$F,MATCH($B4,Listado!$B:$B,0)),"")} -> Sofia
A5: {=IFERROR(INDEX(Listado!$A:$A,MATCH($B5,Listado!$B:$B,0)),"")} -> Ganuzza María Ester | B5: 10956077 | C5: {=IFERROR(INDEX(Listado!$C:$C,MATCH($B5,Listado!$B:$B,0)),"")} -> 1138544794 | D5: {=IFERROR(INDEX(Listado!$D:$D,MATCH($B5,Listado!$B:$B,0)),"")} -> Rivadavia 537 | E5: {=IFERROR(INDEX(Listado!$E:$E,MATCH($B5,Listado!$B:$B,0)),"")} -> 2 | F5: {=IFERROR(INDEX(Listado!$F:$F,MATCH($B5,Listado!$B:$B,0)),"")} -> Sofia
A6: Gonzalez Romero Maria | B6: 94775758 | C6: {=IFERROR(INDEX(Listado!$C:$C,MATCH($B6,Listado!$B:$B,0)),"")} | D6: {=IFERROR(INDEX(Listado!$D:$D,MATCH($B6,Listado!$B:$B,0)),"")} | E6: {=IFERROR(INDEX(Listado!$E:$E,MATCH($B6,Listado!$B:$B,0)),"")} | F6: Sofia
